E:\Repo\MessageExchangeACS\venv\lib\site-packages\django\core\handlers\exception.py : 2018-03-25 20:56:21,128 : ERROR : Function(handle_uncaught_exception) 	 Internal Server Error: /api/v1/auth/register/
Traceback (most recent call last):
  File "E:\Repo\MessageExchangeACS\venv\lib\site-packages\django\core\handlers\exception.py", line 41, in inner
    response = get_response(request)
  File "E:\Repo\MessageExchangeACS\venv\lib\site-packages\django\core\handlers\base.py", line 187, in _get_response
    response = self.process_exception_by_middleware(e, request)
  File "E:\Repo\MessageExchangeACS\venv\lib\site-packages\django\core\handlers\base.py", line 185, in _get_response
    response = wrapped_callback(request, *callback_args, **callback_kwargs)
  File "E:\Repo\MessageExchangeACS\venv\lib\site-packages\django\views\decorators\csrf.py", line 58, in wrapped_view
    return view_func(*args, **kwargs)
  File "E:\Repo\MessageExchangeACS\venv\lib\site-packages\django\views\generic\base.py", line 68, in view
    return self.dispatch(request, *args, **kwargs)
  File "E:\Repo\MessageExchangeACS\venv\lib\site-packages\rest_framework\views.py", line 494, in dispatch
    response = self.handle_exception(exc)
  File "E:\Repo\MessageExchangeACS\venv\lib\site-packages\rest_framework\views.py", line 454, in handle_exception
    self.raise_uncaught_exception(exc)
  File "E:\Repo\MessageExchangeACS\venv\lib\site-packages\rest_framework\views.py", line 491, in dispatch
    response = handler(request, *args, **kwargs)
  File "E:\Repo\MessageExchangeACS\messageExchangeACS\authentication\views.py", line 53, in post
    register_log.info("User registered with data: email {}, First name: {}, Last name: [}".format(
AttributeError: 'NoneType' object has no attribute 'info'
E:\Repo\MessageExchangeACS\venv\lib\site-packages\django\core\handlers\exception.py : 2018-03-25 20:56:44,288 : ERROR : Function(handle_uncaught_exception) 	 Internal Server Error: /api/v1/auth/register/
Traceback (most recent call last):
  File "E:\Repo\MessageExchangeACS\venv\lib\site-packages\django\core\handlers\exception.py", line 41, in inner
    response = get_response(request)
  File "E:\Repo\MessageExchangeACS\venv\lib\site-packages\django\core\handlers\base.py", line 187, in _get_response
    response = self.process_exception_by_middleware(e, request)
  File "E:\Repo\MessageExchangeACS\venv\lib\site-packages\django\core\handlers\base.py", line 185, in _get_response
    response = wrapped_callback(request, *callback_args, **callback_kwargs)
  File "E:\Repo\MessageExchangeACS\venv\lib\site-packages\django\views\decorators\csrf.py", line 58, in wrapped_view
    return view_func(*args, **kwargs)
  File "E:\Repo\MessageExchangeACS\venv\lib\site-packages\django\views\generic\base.py", line 68, in view
    return self.dispatch(request, *args, **kwargs)
  File "E:\Repo\MessageExchangeACS\venv\lib\site-packages\rest_framework\views.py", line 494, in dispatch
    response = self.handle_exception(exc)
  File "E:\Repo\MessageExchangeACS\venv\lib\site-packages\rest_framework\views.py", line 454, in handle_exception
    self.raise_uncaught_exception(exc)
  File "E:\Repo\MessageExchangeACS\venv\lib\site-packages\rest_framework\views.py", line 491, in dispatch
    response = handler(request, *args, **kwargs)
  File "E:\Repo\MessageExchangeACS\messageExchangeACS\authentication\views.py", line 53, in post
    register_log.info("User registered with data: email {}, First name: {}, Last name: [}".format(
AttributeError: 'NoneType' object has no attribute 'info'
E:\Repo\MessageExchangeACS\venv\lib\site-packages\django\core\handlers\exception.py : 2018-03-25 20:57:56,534 : ERROR : Function(handle_uncaught_exception) 	 Internal Server Error: /api/v1/auth/register/
Traceback (most recent call last):
  File "E:\Repo\MessageExchangeACS\venv\lib\site-packages\django\core\handlers\exception.py", line 41, in inner
    response = get_response(request)
  File "E:\Repo\MessageExchangeACS\venv\lib\site-packages\django\core\handlers\base.py", line 187, in _get_response
    response = self.process_exception_by_middleware(e, request)
  File "E:\Repo\MessageExchangeACS\venv\lib\site-packages\django\core\handlers\base.py", line 185, in _get_response
    response = wrapped_callback(request, *callback_args, **callback_kwargs)
  File "E:\Repo\MessageExchangeACS\venv\lib\site-packages\django\views\decorators\csrf.py", line 58, in wrapped_view
    return view_func(*args, **kwargs)
  File "E:\Repo\MessageExchangeACS\venv\lib\site-packages\django\views\generic\base.py", line 68, in view
    return self.dispatch(request, *args, **kwargs)
  File "E:\Repo\MessageExchangeACS\venv\lib\site-packages\rest_framework\views.py", line 494, in dispatch
    response = self.handle_exception(exc)
  File "E:\Repo\MessageExchangeACS\venv\lib\site-packages\rest_framework\views.py", line 454, in handle_exception
    self.raise_uncaught_exception(exc)
  File "E:\Repo\MessageExchangeACS\venv\lib\site-packages\rest_framework\views.py", line 491, in dispatch
    response = handler(request, *args, **kwargs)
  File "E:\Repo\MessageExchangeACS\messageExchangeACS\authentication\views.py", line 53, in post
    register_log.debug("User registered with data: email {}, First name: {}, Last name: [}".format(
AttributeError: 'NoneType' object has no attribute 'debug'
E:\Repo\MessageExchangeACS\venv\lib\site-packages\django\core\handlers\base.py : 2018-03-26 21:18:11,807 : WARNING : Function(get_response) 	 Not Found: /api/v1/auth/institute/
E:\Repo\MessageExchangeACS\venv\lib\site-packages\django\core\handlers\base.py : 2018-03-26 21:31:04,327 : WARNING : Function(get_response) 	 Not Found: /favicon.ico
E:\Repo\MessageExchangeACS\venv\lib\site-packages\django\core\handlers\base.py : 2018-03-26 21:34:52,959 : WARNING : Function(get_response) 	 Not Found: /http:/127.0.0.1:8000/api/v1/auth/login/
E:\Repo\MessageExchangeACS\venv\lib\site-packages\django\core\handlers\exception.py : 2018-03-26 21:36:13,715 : ERROR : Function(handle_uncaught_exception) 	 Internal Server Error: /api/v1/institute/
Traceback (most recent call last):
  File "E:\Repo\MessageExchangeACS\venv\lib\site-packages\django\core\handlers\exception.py", line 41, in inner
    response = get_response(request)
  File "E:\Repo\MessageExchangeACS\venv\lib\site-packages\django\core\handlers\base.py", line 187, in _get_response
    response = self.process_exception_by_middleware(e, request)
  File "E:\Repo\MessageExchangeACS\venv\lib\site-packages\django\core\handlers\base.py", line 185, in _get_response
    response = wrapped_callback(request, *callback_args, **callback_kwargs)
  File "E:\Repo\MessageExchangeACS\venv\lib\site-packages\django\views\decorators\csrf.py", line 58, in wrapped_view
    return view_func(*args, **kwargs)
  File "E:\Repo\MessageExchangeACS\venv\lib\site-packages\django\views\generic\base.py", line 68, in view
    return self.dispatch(request, *args, **kwargs)
  File "E:\Repo\MessageExchangeACS\venv\lib\site-packages\rest_framework\views.py", line 477, in dispatch
    request = self.initialize_request(request, *args, **kwargs)
  File "E:\Repo\MessageExchangeACS\venv\lib\site-packages\rest_framework\views.py", line 379, in initialize_request
    authenticators=self.get_authenticators(),
  File "E:\Repo\MessageExchangeACS\venv\lib\site-packages\rest_framework\views.py", line 273, in get_authenticators
    return [auth() for auth in self.authentication_classes]
TypeError: 'type' object is not iterable
E:\Repo\MessageExchangeACS\messageExchangeACS\authentication\signals.py : 2018-03-26 21:40:23,261 : ERROR : Function(log_user_logged_in_success) 	 log_user_logged_in request: <rest_framework.request.Request object at 0x047410B0>, error: 'UserAccount' object has no attribute 'username'
E:\Repo\MessageExchangeACS\messageExchangeACS\authentication\signals.py : 2018-03-26 21:46:17,752 : ERROR : Function(log_user_logged_in_success) 	 log_user_logged_in request: <rest_framework.request.Request object at 0x0428D150>, error: 'UserAccount' object has no attribute 'username'
E:\Repo\MessageExchangeACS\messageExchangeACS\authentication\signals.py : 2018-03-26 21:51:38,896 : ERROR : Function(log_user_logged_in_success) 	 log_user_logged_in request: <rest_framework.request.Request object at 0x03BEF0D0>, error: 'UserAccount' object has no attribute 'username'
E:\Repo\MessageExchangeACS\messageExchangeACS\authentication\signals.py : 2018-03-26 21:53:10,299 : ERROR : Function(log_user_logged_in_success) 	 log_user_logged_in request: <rest_framework.request.Request object at 0x03BEFF30>, error: 'UserAccount' object has no attribute 'username'
E:\Repo\MessageExchangeACS\messageExchangeACS\authentication\signals.py : 2018-03-26 21:55:33,788 : ERROR : Function(log_user_logged_in_success) 	 log_user_logged_in request: <rest_framework.request.Request object at 0x03C110D0>, error: 'UserAccount' object has no attribute 'username'
E:\Repo\MessageExchangeACS\venv\lib\site-packages\django\core\handlers\exception.py : 2018-03-26 22:06:52,851 : ERROR : Function(handle_uncaught_exception) 	 Internal Server Error: /api/v1/institute/
Traceback (most recent call last):
  File "E:\Repo\MessageExchangeACS\venv\lib\site-packages\django\core\handlers\exception.py", line 41, in inner
    response = get_response(request)
  File "E:\Repo\MessageExchangeACS\venv\lib\site-packages\django\core\handlers\base.py", line 187, in _get_response
    response = self.process_exception_by_middleware(e, request)
  File "E:\Repo\MessageExchangeACS\venv\lib\site-packages\django\core\handlers\base.py", line 185, in _get_response
    response = wrapped_callback(request, *callback_args, **callback_kwargs)
  File "E:\Repo\MessageExchangeACS\venv\lib\site-packages\django\views\decorators\csrf.py", line 58, in wrapped_view
    return view_func(*args, **kwargs)
  File "E:\Repo\MessageExchangeACS\venv\lib\site-packages\django\views\generic\base.py", line 68, in view
    return self.dispatch(request, *args, **kwargs)
  File "E:\Repo\MessageExchangeACS\venv\lib\site-packages\rest_framework\views.py", line 494, in dispatch
    response = self.handle_exception(exc)
  File "E:\Repo\MessageExchangeACS\venv\lib\site-packages\rest_framework\views.py", line 454, in handle_exception
    self.raise_uncaught_exception(exc)
  File "E:\Repo\MessageExchangeACS\venv\lib\site-packages\rest_framework\views.py", line 491, in dispatch
    response = handler(request, *args, **kwargs)
TypeError: get() missing 1 required positional argument: 'pk'
E:\Repo\MessageExchangeACS\venv\lib\site-packages\django\core\handlers\exception.py : 2018-03-26 22:08:20,894 : ERROR : Function(handle_uncaught_exception) 	 Internal Server Error: /api/v1/institute/1/
Traceback (most recent call last):
  File "E:\Repo\MessageExchangeACS\venv\lib\site-packages\django\core\handlers\exception.py", line 41, in inner
    response = get_response(request)
  File "E:\Repo\MessageExchangeACS\venv\lib\site-packages\django\core\handlers\base.py", line 187, in _get_response
    response = self.process_exception_by_middleware(e, request)
  File "E:\Repo\MessageExchangeACS\venv\lib\site-packages\django\core\handlers\base.py", line 185, in _get_response
    response = wrapped_callback(request, *callback_args, **callback_kwargs)
  File "E:\Repo\MessageExchangeACS\venv\lib\site-packages\django\views\decorators\csrf.py", line 58, in wrapped_view
    return view_func(*args, **kwargs)
  File "E:\Repo\MessageExchangeACS\venv\lib\site-packages\django\views\generic\base.py", line 68, in view
    return self.dispatch(request, *args, **kwargs)
  File "E:\Repo\MessageExchangeACS\venv\lib\site-packages\rest_framework\views.py", line 494, in dispatch
    response = self.handle_exception(exc)
  File "E:\Repo\MessageExchangeACS\venv\lib\site-packages\rest_framework\views.py", line 454, in handle_exception
    self.raise_uncaught_exception(exc)
  File "E:\Repo\MessageExchangeACS\venv\lib\site-packages\rest_framework\views.py", line 491, in dispatch
    response = handler(request, *args, **kwargs)
TypeError: get() got an unexpected keyword argument 'institute_id'
E:\Repo\MessageExchangeACS\venv\lib\site-packages\django\core\handlers\base.py : 2018-03-26 22:38:18,560 : WARNING : Function(get_response) 	 Not Found: /api/v1/auh/login/
E:\Repo\MessageExchangeACS\messageExchangeACS\authentication\signals.py : 2018-03-26 22:38:25,639 : ERROR : Function(log_user_logged_in_success) 	 log_user_logged_in request: <rest_framework.request.Request object at 0x041C3D70>, error: 'UserAccount' object has no attribute 'username'
E:\Repo\MessageExchangeACS\messageExchangeACS\authentication\signals.py : 2018-04-09 20:26:47,651 : ERROR : Function(log_user_logged_in_success) 	 log_user_logged_in request: <rest_framework.request.Request object at 0x04682BB0>, error: 'UserAccount' object has no attribute 'username'
E:\Repo\MessageExchangeACS\venv\lib\site-packages\django\core\handlers\exception.py : 2018-04-09 20:27:50,653 : ERROR : Function(handle_uncaught_exception) 	 Internal Server Error: /api/v1/institute/
Traceback (most recent call last):
  File "E:\Repo\MessageExchangeACS\venv\lib\site-packages\django\core\handlers\exception.py", line 41, in inner
    response = get_response(request)
  File "E:\Repo\MessageExchangeACS\venv\lib\site-packages\django\core\handlers\base.py", line 187, in _get_response
    response = self.process_exception_by_middleware(e, request)
  File "E:\Repo\MessageExchangeACS\venv\lib\site-packages\django\core\handlers\base.py", line 185, in _get_response
    response = wrapped_callback(request, *callback_args, **callback_kwargs)
  File "E:\Repo\MessageExchangeACS\venv\lib\site-packages\django\views\decorators\csrf.py", line 58, in wrapped_view
    return view_func(*args, **kwargs)
  File "E:\Repo\MessageExchangeACS\venv\lib\site-packages\django\views\generic\base.py", line 68, in view
    return self.dispatch(request, *args, **kwargs)
  File "E:\Repo\MessageExchangeACS\venv\lib\site-packages\rest_framework\views.py", line 494, in dispatch
    response = self.handle_exception(exc)
  File "E:\Repo\MessageExchangeACS\venv\lib\site-packages\rest_framework\views.py", line 454, in handle_exception
    self.raise_uncaught_exception(exc)
  File "E:\Repo\MessageExchangeACS\venv\lib\site-packages\rest_framework\views.py", line 491, in dispatch
    response = handler(request, *args, **kwargs)
TypeError: get() missing 1 required positional argument: 'institute_id'
E:\Repo\MessageExchangeACS\venv\lib\site-packages\django\core\handlers\exception.py : 2018-04-09 20:40:48,386 : ERROR : Function(handle_uncaught_exception) 	 Internal Server Error: /api/v1/institute/
Traceback (most recent call last):
  File "E:\Repo\MessageExchangeACS\venv\lib\site-packages\django\core\handlers\exception.py", line 41, in inner
    response = get_response(request)
  File "E:\Repo\MessageExchangeACS\venv\lib\site-packages\django\core\handlers\base.py", line 187, in _get_response
    response = self.process_exception_by_middleware(e, request)
  File "E:\Repo\MessageExchangeACS\venv\lib\site-packages\django\core\handlers\base.py", line 185, in _get_response
    response = wrapped_callback(request, *callback_args, **callback_kwargs)
  File "E:\Repo\MessageExchangeACS\venv\lib\site-packages\django\views\decorators\csrf.py", line 58, in wrapped_view
    return view_func(*args, **kwargs)
  File "E:\Repo\MessageExchangeACS\venv\lib\site-packages\django\views\generic\base.py", line 68, in view
    return self.dispatch(request, *args, **kwargs)
  File "E:\Repo\MessageExchangeACS\venv\lib\site-packages\rest_framework\views.py", line 494, in dispatch
    response = self.handle_exception(exc)
  File "E:\Repo\MessageExchangeACS\venv\lib\site-packages\rest_framework\views.py", line 454, in handle_exception
    self.raise_uncaught_exception(exc)
  File "E:\Repo\MessageExchangeACS\venv\lib\site-packages\rest_framework\views.py", line 491, in dispatch
    response = handler(request, *args, **kwargs)
TypeError: get() missing 1 required positional argument: 'institute_id'
E:\Repo\MessageExchangeACS\venv\lib\site-packages\django\core\handlers\exception.py : 2018-04-09 20:41:15,743 : ERROR : Function(handle_uncaught_exception) 	 Internal Server Error: /api/v1/institute/
Traceback (most recent call last):
  File "E:\Repo\MessageExchangeACS\venv\lib\site-packages\rest_framework\fields.py", line 441, in get_attribute
    return get_attribute(instance, self.source_attrs)
  File "E:\Repo\MessageExchangeACS\venv\lib\site-packages\rest_framework\fields.py", line 100, in get_attribute
    instance = getattr(instance, attr)
AttributeError: 'QuerySet' object has no attribute 'name'

During handling of the above exception, another exception occurred:

Traceback (most recent call last):
  File "E:\Repo\MessageExchangeACS\venv\lib\site-packages\django\core\handlers\exception.py", line 41, in inner
    response = get_response(request)
  File "E:\Repo\MessageExchangeACS\venv\lib\site-packages\django\core\handlers\base.py", line 187, in _get_response
    response = self.process_exception_by_middleware(e, request)
  File "E:\Repo\MessageExchangeACS\venv\lib\site-packages\django\core\handlers\base.py", line 185, in _get_response
    response = wrapped_callback(request, *callback_args, **callback_kwargs)
  File "E:\Repo\MessageExchangeACS\venv\lib\site-packages\django\views\decorators\csrf.py", line 58, in wrapped_view
    return view_func(*args, **kwargs)
  File "E:\Repo\MessageExchangeACS\venv\lib\site-packages\django\views\generic\base.py", line 68, in view
    return self.dispatch(request, *args, **kwargs)
  File "E:\Repo\MessageExchangeACS\venv\lib\site-packages\rest_framework\views.py", line 494, in dispatch
    response = self.handle_exception(exc)
  File "E:\Repo\MessageExchangeACS\venv\lib\site-packages\rest_framework\views.py", line 454, in handle_exception
    self.raise_uncaught_exception(exc)
  File "E:\Repo\MessageExchangeACS\venv\lib\site-packages\rest_framework\views.py", line 491, in dispatch
    response = handler(request, *args, **kwargs)
  File "E:\Repo\MessageExchangeACS\messageExchangeACS\institute\views.py", line 27, in get
    return Response(response.data)
  File "E:\Repo\MessageExchangeACS\venv\lib\site-packages\rest_framework\serializers.py", line 537, in data
    ret = super(Serializer, self).data
  File "E:\Repo\MessageExchangeACS\venv\lib\site-packages\rest_framework\serializers.py", line 262, in data
    self._data = self.to_representation(self.instance)
  File "E:\Repo\MessageExchangeACS\venv\lib\site-packages\rest_framework\serializers.py", line 491, in to_representation
    attribute = field.get_attribute(instance)
  File "E:\Repo\MessageExchangeACS\venv\lib\site-packages\rest_framework\fields.py", line 462, in get_attribute
    raise type(exc)(msg)
AttributeError: Got AttributeError when attempting to get a value for field `name` on serializer `InstituteSerializer`.
The serializer field might be named incorrectly and not match any attribute or key on the `QuerySet` instance.
Original exception text was: 'QuerySet' object has no attribute 'name'.
E:\Repo\MessageExchangeACS\venv\lib\site-packages\django\core\handlers\exception.py : 2018-04-09 20:42:02,009 : ERROR : Function(handle_uncaught_exception) 	 Internal Server Error: /api/v1/institute/
Traceback (most recent call last):
  File "E:\Repo\MessageExchangeACS\venv\lib\site-packages\rest_framework\fields.py", line 441, in get_attribute
    return get_attribute(instance, self.source_attrs)
  File "E:\Repo\MessageExchangeACS\venv\lib\site-packages\rest_framework\fields.py", line 100, in get_attribute
    instance = getattr(instance, attr)
AttributeError: 'QuerySet' object has no attribute 'name'

During handling of the above exception, another exception occurred:

Traceback (most recent call last):
  File "E:\Repo\MessageExchangeACS\venv\lib\site-packages\django\core\handlers\exception.py", line 41, in inner
    response = get_response(request)
  File "E:\Repo\MessageExchangeACS\venv\lib\site-packages\django\core\handlers\base.py", line 187, in _get_response
    response = self.process_exception_by_middleware(e, request)
  File "E:\Repo\MessageExchangeACS\venv\lib\site-packages\django\core\handlers\base.py", line 185, in _get_response
    response = wrapped_callback(request, *callback_args, **callback_kwargs)
  File "E:\Repo\MessageExchangeACS\venv\lib\site-packages\django\views\decorators\csrf.py", line 58, in wrapped_view
    return view_func(*args, **kwargs)
  File "E:\Repo\MessageExchangeACS\venv\lib\site-packages\django\views\generic\base.py", line 68, in view
    return self.dispatch(request, *args, **kwargs)
  File "E:\Repo\MessageExchangeACS\venv\lib\site-packages\rest_framework\views.py", line 494, in dispatch
    response = self.handle_exception(exc)
  File "E:\Repo\MessageExchangeACS\venv\lib\site-packages\rest_framework\views.py", line 454, in handle_exception
    self.raise_uncaught_exception(exc)
  File "E:\Repo\MessageExchangeACS\venv\lib\site-packages\rest_framework\views.py", line 491, in dispatch
    response = handler(request, *args, **kwargs)
  File "E:\Repo\MessageExchangeACS\messageExchangeACS\institute\views.py", line 27, in get
    return Response(response.data)
  File "E:\Repo\MessageExchangeACS\venv\lib\site-packages\rest_framework\serializers.py", line 537, in data
    ret = super(Serializer, self).data
  File "E:\Repo\MessageExchangeACS\venv\lib\site-packages\rest_framework\serializers.py", line 262, in data
    self._data = self.to_representation(self.instance)
  File "E:\Repo\MessageExchangeACS\venv\lib\site-packages\rest_framework\serializers.py", line 491, in to_representation
    attribute = field.get_attribute(instance)
  File "E:\Repo\MessageExchangeACS\venv\lib\site-packages\rest_framework\fields.py", line 462, in get_attribute
    raise type(exc)(msg)
AttributeError: Got AttributeError when attempting to get a value for field `name` on serializer `InstituteSerializer`.
The serializer field might be named incorrectly and not match any attribute or key on the `QuerySet` instance.
Original exception text was: 'QuerySet' object has no attribute 'name'.
E:\Repo\MessageExchangeACS\venv\lib\site-packages\django\core\handlers\exception.py : 2018-04-09 20:45:01,082 : ERROR : Function(handle_uncaught_exception) 	 Internal Server Error: /api/v1/institute/1/
Traceback (most recent call last):
  File "E:\Repo\MessageExchangeACS\venv\lib\site-packages\django\db\backends\utils.py", line 65, in execute
    return self.cursor.execute(sql, params)
psycopg2.ProgrammingError: relation "department_department" does not exist
LINE 1: DELETE FROM "department_department" WHERE "department_depart...
                    ^


The above exception was the direct cause of the following exception:

Traceback (most recent call last):
  File "E:\Repo\MessageExchangeACS\venv\lib\site-packages\django\core\handlers\exception.py", line 41, in inner
    response = get_response(request)
  File "E:\Repo\MessageExchangeACS\venv\lib\site-packages\django\core\handlers\base.py", line 187, in _get_response
    response = self.process_exception_by_middleware(e, request)
  File "E:\Repo\MessageExchangeACS\venv\lib\site-packages\django\core\handlers\base.py", line 185, in _get_response
    response = wrapped_callback(request, *callback_args, **callback_kwargs)
  File "E:\Repo\MessageExchangeACS\venv\lib\site-packages\django\views\decorators\csrf.py", line 58, in wrapped_view
    return view_func(*args, **kwargs)
  File "E:\Repo\MessageExchangeACS\venv\lib\site-packages\django\views\generic\base.py", line 68, in view
    return self.dispatch(request, *args, **kwargs)
  File "E:\Repo\MessageExchangeACS\venv\lib\site-packages\rest_framework\views.py", line 494, in dispatch
    response = self.handle_exception(exc)
  File "E:\Repo\MessageExchangeACS\venv\lib\site-packages\rest_framework\views.py", line 454, in handle_exception
    self.raise_uncaught_exception(exc)
  File "E:\Repo\MessageExchangeACS\venv\lib\site-packages\rest_framework\views.py", line 491, in dispatch
    response = handler(request, *args, **kwargs)
  File "E:\Repo\MessageExchangeACS\messageExchangeACS\institute\views.py", line 47, in delete
    institute.delete()
  File "E:\Repo\MessageExchangeACS\venv\lib\site-packages\django\db\models\base.py", line 973, in delete
    return collector.delete()
  File "E:\Repo\MessageExchangeACS\venv\lib\site-packages\django\db\models\deletion.py", line 284, in delete
    count = qs._raw_delete(using=self.using)
  File "E:\Repo\MessageExchangeACS\venv\lib\site-packages\django\db\models\query.py", line 631, in _raw_delete
    return sql.DeleteQuery(self.model).delete_qs(self, using)
  File "E:\Repo\MessageExchangeACS\venv\lib\site-packages\django\db\models\sql\subqueries.py", line 80, in delete_qs
    cursor = self.get_compiler(using).execute_sql(CURSOR)
  File "E:\Repo\MessageExchangeACS\venv\lib\site-packages\django\db\models\sql\compiler.py", line 886, in execute_sql
    raise original_exception
  File "E:\Repo\MessageExchangeACS\venv\lib\site-packages\django\db\models\sql\compiler.py", line 876, in execute_sql
    cursor.execute(sql, params)
  File "E:\Repo\MessageExchangeACS\venv\lib\site-packages\django\db\backends\utils.py", line 80, in execute
    return super(CursorDebugWrapper, self).execute(sql, params)
  File "E:\Repo\MessageExchangeACS\venv\lib\site-packages\django\db\backends\utils.py", line 65, in execute
    return self.cursor.execute(sql, params)
  File "E:\Repo\MessageExchangeACS\venv\lib\site-packages\django\db\utils.py", line 94, in __exit__
    six.reraise(dj_exc_type, dj_exc_value, traceback)
  File "E:\Repo\MessageExchangeACS\venv\lib\site-packages\django\utils\six.py", line 685, in reraise
    raise value.with_traceback(tb)
  File "E:\Repo\MessageExchangeACS\venv\lib\site-packages\django\db\backends\utils.py", line 65, in execute
    return self.cursor.execute(sql, params)
django.db.utils.ProgrammingError: relation "department_department" does not exist
LINE 1: DELETE FROM "department_department" WHERE "department_depart...
                    ^

